Workbook

Sheet TB AWAL
A2: TRIAL BALANCE
A5: ACC.NO | B5: ACCOUNT NAME | C5: DEBIT | D5: CREDIT
A6: 1-1100 | B6: Cash in bank | C6: 90839200
A7: 1-1200 | B7: Petty Cash | C7: 3500000
A8: 1-1300 | B8: Accounts Receivable | C8: 17760000
A9: 1-1400 | B9: Allowance for Doubtful Debt | D9: 2500000
A10: 1-1500 | B10: Merchandise Inventory | C10: 7283500
A11: 1-1600 | B11: Store Supplies | C11: 3720000
A12: 1-1700 | B12: Prepaid Insurance | C12: 1230000
A13: 1-2100 | B13: Equipment at Cost | C13: 7245000
A14: 1-2110 | B14: Equipment Accum Dep | D14: 3421250
A15: 2-1100 | B15: Accounts Payable | D15: 12543000
A16: 2-1200 | B16: Expense Payable | D16: 4405000
A17: 2-1400 | B17: PPN Payable
A18: 2-1500 | B18: PPN Outcome | D18: 1243000
A19: 2-1600 | B19: PPN Income | C19: 1254000
A20: 3-1100 | B20: KOPMEN SBW Capital | D20: 101298000
A21: 3-1200 | B21: KOPMEN SBW Drawing | C21: 150000
A22: 3-1300 | B22: Income Summary
A23: 4-1100 | B23: Sales | D23: 7571450
A24: 4-1200 | B24: Sales Retur | C24: -
A25: 4-1400 | B25: Freight Collected
A26: 5-1100 | B26: Cost of goods Sold | C26: -
A27: 5-1200 | B27: Freight Paid | C27: -
A28: 6-1100 | B28: Electricity, Internet & Water expenses
A29: 6-1200 | B29: Store Supplies Expenses
A30: 6-1300 | B30: Bad Debt Expense | C30: -
A31: 6-1400 | B31: Depreciation Expense | C31: -
A32: 6-1500 | B32: Insurance Expense | C32: -
A33: 6-1700 | B33: Wages & Salaries
A34: 6-1800 | B34: Other Operating Expense
C35: =SUM(C6:C34) -> 132981700 | D35: =SUM(D9:D23) -> 132981700

Sheet CRJ
A2: CASH RECEIPT JOURNAL
A5: DATE | B5: DOC. NO | C5: DESCRIPTION | D5: REF | E5: DEBET | H5: CREDIT | L5: RECAPITULATION
E6: CASH IN BANK | F6: OTHER | H6: ACCOUNTS RECEIVABLE | I6: OTHER | L6: DEBET | N6: CREDIT
F7: ACC.NO | G7: AMOUNT | I7: ACC. NO | J7: AMOUNT | L7: ACC. NO | M7: AMOUNT | N7: ACC. NO | O7: AMOUNT
A8: Juni | L8: 1-1100 √ | M8: =SUM(E9:E20) -> 39972325 | N8: 1-1300 √ | O8: =SUM(H12:H19) -> 24546100
A9: 3 | B9: SAL.21433 | C9: Mariana Putri Betyani | E9: =SUM(J9:J10) -> 5422350 | I9: ='TB AWAL'!A23 -> 4-1100 | J9: 4885000 | L9: 5-1100 √ | M9: =SUM(G11:G22) -> 11772500 | N9: 1-1500 √ | O9: =SUM(J11+J16+J22) -> 11772500
I10: 2-1500 | J10: 537350 | N10: 2-1500 √ | O10: =SUM(J10+J15+J21) -> 1528725
F11: 5-1100 | G11: ='IC (1)'!H10+'IC (1)'!H32+'IC(2)'!H30 -> 3650000 | I11: 1-1500 | J11: ='IC (1)'!H10+'IC (1)'!H32+'IC(2)'!H30 -> 3650000 | N11: 4-1100 √ | O11: =SUM(J9+J14+J20) -> 13897500
A12: 9 | B12: BKM-256 | C12: Toko Makmur | E12: 5772000 | H12: 5772000 | M12: =SUM(M8+M9) -> 51744825 | O12: =SUM(O8+O9+O10+O11) -> 51744825
A13: 14 | B13: BKM-257 | C13: Sri Lestari | E13: 2775000 | H13: 2775000
A14: 15 | B14: SAL.21434 | C14: Toko Sofiyah | E14: =SUM(J14:J15) -> 6102225 | I14: 4-1100 | J14: 5497500
I15: 2-1500 | J15: 604725
F16: 5-1100 | G16: ='IC (1)'!H13+'IC (1)'!H35+'IC(2)'!H14+'IC(2)'!H32 -> 4857500 | I16: 1-1500 | J16: ='IC (1)'!H13+'IC (1)'!H35+'IC(2)'!H14+'IC(2)'!H32 -> 4857500
A17: 18 | B17: BKM-258 | C17: Mariana Putri Betyani | E17: 5106000 | H17: 5106000
A18: 26 | B18: BKM-259 | C18: Toko Sofiyah | E18: 4107000 | H18: 4107000
A19: 28 | B19: BKM-260 | C19: Sri Lestari | E19: 6786100 | H19: 6786100
A20: 29 | B20: SAL.21435 | C20: Toko Makmur | E20: =J20+J21 -> 3901650 | I20: ='TB AWAL'!A23 -> 4-1100 | J20: 3515000
I21: 2-1500 | J21: 386650
E22: (1-1100) | F22: 5-1100 | G22: ='IC (1)'!H37+'IC(2)'!H35 -> 3265000 | H22: (1-300) | I22: 1-1500 | J22: ='IC (1)'!H37+'IC(2)'!H35 -> 3265000
E23: =SUM(E9:E20) -> 39972325 | G23: =SUM(G11:G22) -> 11772500 | H23: =SUM(H12:H19) -> 24546100 | J23: =SUM(J9:J22) -> 27198725

Sheet CPJ
A2: CASH PAYMENT JOURNAL
A5: DATE | B5: DOC. NO | C5: DESCRIPTION | D5: REF | E5: DEBET | H5: CREDIT | L5: RECAPITULATION
E6: ACCOUNTS PAYABLE | F6: OTHER | H6: CASH IN BANK | I6: OTHER | L6: DEBET | N6: CREDIT
F7: ACC.NO | G7: AMOUNT | I7: ACC. NO | J7: AMOUNT | L7: ACC. NO | M7: AMOUNT | N7: ACC. NO | O7: AMOUNT
A8: Juni | L8: 2-1100 √ | M8: =E10 -> 2442000 | N8: 1-1100 √ | O8: =H21 -> 8224143
A9: 2 | B9: BKK-254 | C9: Gaji Karyawan | F9: ='TB AWAL'!A16 -> 2-1200 | G9: 1725000 | H9: 1725000 | L9: 2-1200 √ | M9: =G9 -> 1725000
A10: 13 | B10: BKK-361 | C10: PT.PB Tunggal Perkasa | E10: 2442000 | H10: 2442000 | L10: 6-1100 √ | M10: =G11+G13 -> 3607143
A11: 20 | B11: BKK-362 | C11: PLN&Internet | F11: 6-1100 | G11: 2680000 | H11: 2680000 | L11: 3-1200 √ | M11: =H12 -> 450000
A12: 21 | B12: PV.751 | C12: Prive | F12: 3-1200 | G12: 450000 | H12: 450000
A13: 25 | B13: BKK-363 | C13: PDAM | F13: 6-1100 | G13: 927143 | H13: 927143 | M13: =SUM(M8+M9+M10+M11) -> 8224143 | O13: =O8 -> 8224143
E20: (2-1100) | H20: (1=1100)
E21: =SUM(E10) -> 2442000 | G21: =SUM(G9:G13) -> 5782143 | H21: =SUM(H9:H13) -> 8224143

Sheet SJ
A2: SALES JOURNAL
A5: DATE | B5: DOC. NO | C5: DESCRIPTION | D5: REF | E5: DEBET | H5: CREDIT | M5: RECAPITULATION
E6: ACCOUNTS RECEIVABLE | F6: OTHER | H6: SALES | I6: VAT OUT | J6: OTHER | M6: DEBET | O6: CREDIT
F7: ACC.NO | G7: AMOUNT | J7: ACC. NO | K7: AMOUNT | M7: ACC. NO | N7: AMOUNT | O7: ACC. NO | P7: AMOUNT
A8: Juni | M8: 1-1300 √ | N8: =SUM(E9:E11) -> 13114100 | O8: 1-1500 √ | P8: =SUM(K10+K12) -> 10320000
A9: 7 | B9: FT.01 | C9: Sri Lestari | E9: =SUM(H9:I9:K9) -> 6786100 | H9: 5825000 | I9: 640750 | J9: 4-1400 | K9: 320350 | M9: 5-1100 √ | N9: =SUM(G10:G12) -> 10320000 | O9: 2-1500 √ | P9: =SUM(I9+I11) -> 1238050
F10: 5-1100 | G10: ='IC (1)'!H12+'IC (1)'!H33+'IC(2)'!H12+'IC(2)'!H13 -> 5260000 | J10: 1-1500 | K10: ='IC (1)'!H12+'IC (1)'!H33+'IC(2)'!H12+'IC(2)'!H13 -> 5260000 | O10: 4-1100 √ | P10: =SUM(H9:H11) -> 11255000
A11: 24 | B11: FT.02 | C11: Toko Sofiyah | E11: =SUM(H11:I11:K11) -> 6328000 | H11: 5430000 | I11: 597300 | J11: 4-1400 | K11: 300700 | O11: 4-1400 √ | P11: =SUM(K9+K11) -> 621050
F12: 5-1100 | G12: ='IC (1)'!H36+'IC(2)'!H15+'IC(2)'!H34 -> 5060000 | J12: 1-1500 | K12: ='IC (1)'!H36+'IC(2)'!H15+'IC(2)'!H34 -> 5060000
N13: =SUM(N8+N9) -> 23434100 | P13: =SUM(P8+P9+P10+P11) -> 23434100
E19: (1-1300) | H19: (4-1100) | I19: (2-1500)
E20: =SUM(E9:E11) -> 13114100 | G20: =SUM(G10:G12) -> 10320000 | H20: =SUM(H9:H11) -> 11255000 | I20: =SUM(I9:I11) -> 1238050 | K20: =SUM(K9:K12) -> 10941050
G29: =H9+I9 -> 6465750

Sheet PJ
A2: PURCHASE JOURNAL
A5: DATE | B5: DOC. NO | C5: DESCRIPTION | D5: REF | E5: DEBET | I5: CREDIT | M5: RECAPITULATION
E6: MERCHANDISE INVENTORY | F6: VAT IN | G6: OTHER | I6: ACCOUNTS PAYABLE | J6: OTHER | M6: DEBET | O6: CREDIT
G7: ACC.NO | H7: AMOUNT | J7: ACC. NO | K7: AMOUNT | M7: ACC. NO | N7: AMOUNT | O7: ACC. NO | P7: AMOUNT
A8: Juni | M8: 1-1500 √ | N8: =SUM(E9:E12) -> 18655000 | O8: 2-1100 √ | P8: =SUM(I9:I12) -> 21373450
A9: 2 | B9: 1444 | C9: Shoppe Indonesia | E9: 2760000 | I9: 2760000 | M9: 2-1600 √ | N9: =SUM(F10:F12) -> 1748450
A10: 6 | B10: 102 | C10: PT PB Tunggal Perkasa | E10: 3250000 | F10: 357500 | G10: ='TB AWAL'!A27 -> 5-1200 | H10: 250000 | I10: =SUM(H10+F10+E10) -> 3857500 | M10: 5-1200 √ | N10: =SUM(H10:H12) -> 970000
A11: 8 | B11: 6825 | C11: PT Sumber Lancar | E11: 1530000 | F11: 168300 | G11: ='TB AWAL'!A27 -> 5-1200 | H11: 300000 | I11: =SUM(E11:F11:H11) -> 1998300
A12: 9 | B12: PN567.9 | C12: PT Cahaya Abadi | E12: 11115000 | F12: 1222650 | G12: ='TB AWAL'!A27 -> 5-1200 | H12: 420000 | I12: =SUM(E12:F12:H12) -> 12757650 | N12: =SUM(N8+N9+N10) -> 21373450 | P12: =P8 -> 21373450
E19: (1-1500) | H19: (5-1200) | I19: (2-1100)
E20: =SUM(E9:E12) -> 18655000 | F20: =SUM(F10:F12) -> 1748450 | H20: =SUM(H10:H12) -> 970000 | I20: =SUM(I9:I12) -> 21373450

Sheet PC
A2: PETTY CASH JOURNAL
A5: DATE | B5: DOC. NO | C5: DESCRIPTION | D5: REF | E5: DEBIT | G5: CREDIT | K5: RECAPITULATION
E6: ACC. NO | F6: AMOUNT | G6: ACC. NO | H6: AMOUNT | K6: DEBET | M6: CREDIT
A7: Juni 2025 | K7: ACC. NO | L7: AMOUNT | M7: ACC. NO | N7: AMOUNT
A8: 4 | B8: VK.120 | C8: Store Supplies | E8: ='TB AWAL'!A11 -> 1-1600 | F8: 448100 | G8: ='TB AWAL'!A7 -> 1-1200 | H8: 448100 | K8: 1-1600 √ | L8: 448100 | M8: 1-1200 √ | N8: =SUM(H8+H9+H10) -> 848100
A9: 16 | B9: VK.121 | C9: Other Operating Expenses | E9: 6-1800 | F9: 400000 | G9: 1-1200 | H9: 400000 | K9: 6-1800 √ | L9: 400000
L11: =SUM(L8+L9) -> 848100 | N11: =N8 -> 848100
F28: (1-600) | H28: (1-200)
C29: TOTAL | F29: =SUM(F8:F10) -> 848100 | H29: =SUM(H8:H10) -> 848100

Sheet GJ
A2: GENERAL JOURNAL
A5: DATE | B5: DOC.NO | C5: DESCRIPTION | D5: REFF | E5: DEBIT | F5: CREDIT | I5: RECAPITULATION
I6: DEBET | K6: CREDIT
A7: Juni 22 | B7: ND6-1 | C7: Utang Dagang | E7: 94350 | I7: ACC. NO | J7: AMOUNT | K7: ACC. NO | L7: AMOUNT
C8: Persediaan Barang Dagang | F8: 85000 | I8: 2-1100 √ | J8: =SUM(E7) -> 94350 | K8: 1-1500 √ | L8: =SUM(F8) -> 85000
C9: PPN Masukan | F9: 9350 | K9: 2-1600 √ | L9: =SUM(F9) -> 9350
J11: =J8 -> 94350 | L11: =SUM(L8+L9) -> 94350
C25: TOTAL | E25: =SUM(E7) -> 94350 | F25: =SUM(F8:F9) -> 94350

Sheet IC (1)
A2: INVENTORY CARD
A5: Beras Pin Pin 5kg
A6: DATE | B6: DOC. NO | C6: IN | F6: OUT | I6: BALANCE
C7: QTY | D7: PRICE | E7: AMOUNT | F7: QTY | G7: PRICE | H7: AMOUNT | I7: QTY | J7: PRICE | K7: AMOUNT
A8: Juni 2025
A9: 1 | I9: 20 | J9: 65000 | K9: =I9*J9 -> 1300000
A10: 3 | B10: SAL.1433 | F10: 20 | G10: 65000 | H10: =G10*F10 -> 1300000 | I10: =I9-F10 -> 0 | J10: 65000 | K10: =J10*I10 -> 0
A11: 6 | B11: 102 | C11: 50 | D11: 65000 | E11: =D11*C11 -> 3250000 | I11: =SUM(I10+C11) -> 50 | J11: 65000 | K11: =J11*I11 -> 3250000
A12: 7 | B12: FT.01 | F12: 20 | G12: 65000 | H12: =F12*G12 -> 1300000 | I12: =I11-F12 -> 30 | J12: 65000 | K12: =I12*J12 -> 1950000
A13: 15 | B13: SAL.1434 | F13: 15 | G13: 65000 | H13: =F13*G13 -> 975000 | I13: =I12-F13 -> 15 | J13: 65000 | K13: =I13*J13 -> 975000
I22: =I13 -> 15 | J22: 65000 | K22: =I22*J22 -> 975000
A27: ITEM : | B27: Indomie Goreng 80 gram
A28: DATE | B28: DOC. NO | C28: IN | F28: OUT | I28: BALANCE
C29: QTY | D29: PRICE | E29: AMOUNT | F29: QTY | G29: PRICE | H29: AMOUNT | I29: QTY | J29: PRICE | K29: AMOUNT
A30: Juni 2025
A31: 1 | I31: 40 | J31: 117000 | K31: =I31*J31 -> 4680000
A32: 3 | B32: SAL.21433 | F32: 15 | G32: =J31 -> 117000 | H32: =G32*F32 -> 1755000 | I32: =I31-F32 -> 25 | J32: 117000 | K32: =I32*J32 -> 2925000
A33: 7 | B33: FT 01 | F33: 25 | G33: =J32 -> 117000 | H33: =F33*G33 -> 2925000 | I33: =I32-F33 -> 0 | J33: 117000 | K33: =I33*J33 -> 0
A34: 9 | B34: PN.567.9 | C34: 95 | D34: =J31 -> 117000 | E34: =C34*D34 -> 11115000 | I34: 95 | J34: =J31 -> 117000 | K34: =I34*J34 -> 11115000
A35: 15 | B35: SAL.21434 | F35: 20 | G35: 117000 | H35: =F35*G35 -> 2340000 | I35: =I34-F35 -> 75 | J35: 117000 | K35: =I35*J35 -> 8775000
A36: 24 | B36: FT.02 | F36: 30 | G36: 117000 | H36: =F36*G36 -> 3510000 | I36: =I35-F36 -> 45 | J36: 117000 | K36: =I36*J36 -> 5265000
A37: 29 | B37: SAL.21435 | F37: 25 | G37: 117000 | H37: =F37*G37 -> 2925000 | I37: =I36-F37 -> 20 | J37: 117000 | K37: =I37*J37 -> 2340000
I43: =I37 -> 20 | J43: 117000 | K43: =I43*J43 -> 2340000

Sheet IC(2)
A2: INVENTORY CARD
A5: ITEM : | B5: Rinso Matic Liq Pro Laundry 4.5L
A6: DATE | B6: DOC. NO | C6: IN | F6: OUT | I6: BALANCE
C7: QTY | D7: PRICE | E7: AMOUNT | F7: QTY | G7: PRICE | H7: AMOUNT | I7: QTY | J7: PRICE | K7: AMOUNT
A8: Juni 2025
A9: 1 | I9: 23 | J9: 34500 | K9: =I9*J9 -> 793500
A10: 2 | B10: 1444 | C10: 80 | D10: 34500 | E10: =D10*C10 -> 2760000 | I10: 23 | J10: =J9 -> 34500 | K10: =K9 -> 793500
I11: 80 | J11: =D10 -> 34500 | K11: =J11*I11 -> 2760000
A12: 7 | B12: FT 01 | F12: 23 | G12: =J10 -> 34500 | H12: =F12*G12 -> 793500 | I12: =I11 -> 80 | J12: 34500 | K12: =I12*J12 -> 2760000
F13: 7 | G13: 34500 | H13: =F13*G13 -> 241500 | I13: =I12-F13 -> 73 | J13: 34500 | K13: =I13*J13 -> 2518500
A14: 15 | B14: 21434 | F14: 25 | G14: 34500 | H14: =F14*G14 -> 862500 | I14: =I13-F14 -> 48 | J14: =J11 -> 34500 | K14: =I14*J14 -> 1656000
A15: 24 | B15: FT.02 | F15: 40 | G15: 34500 | H15: =F15*G15 -> 1380000 | I15: =I14-F15 -> 8 | J15: =J12 -> 34500 | K15: =I15*J15 -> 276000
I21: 8 | J21: 34500 | K21: =I21*J21 -> 276000
A25: ITEM : | B25: Gula Kebon Agung 1Kg
A26: DATE | B26: DOC. NO | C26: IN | F26: OUT | I26: BALANCE
C27: QTY | D27: PRICE | E27: AMOUNT | F27: QTY | G27: PRICE | H27: AMOUNT | I27: QTY | J27: PRICE | K27: AMOUNT
A28: Juni 2025
A29: 1 | I29: 35 | J29: 17000 | K29: =I29*J29 -> 595000
A30: 3 | B30: SAL.21433 | F30: 35 | G30: 17000 | H30: =F30*G30 -> 595000 | I30: 0 | J30: 17000 | K30: =I30*J30 -> 0
A31: 8 | B31: 6825 | C31: 90 | D31: =J29 -> 17000 | E31: =C31*D31 -> 1530000 | I31: =I30+C31 -> 90 | J31: 17000 | K31: =I31*J31 -> 1530000
A32: 15 | B32: SAL.21434 | F32: 40 | G32: 17000 | H32: =F32*G32 -> 680000 | I32: =I31-F32 -> 50 | J32: 17000 | K32: =I32*J32 -> 850000
A33: 22 | B33: ND6-1 | C33: -5 | D33: 17500 | E33: =C33*D33 -> -87500 | I33: =I32+C33 -> 45 | J33: 17000 | K33: =I33*J33 -> 765000
A34: 24 | B34: FT.02 | F34: 10 | G34: 17000 | H34: =F34*G34 -> 170000 | I34: =I33-F34 -> 35 | J34: 17000 | K34: =I34*J34 -> 595000
A35: 29 | B35: SAL.21435 | F35: 20 | G35: 17000 | H35: =F35*G35 -> 340000 | I35: =I34-F35 -> 15 | J35: 17000 | K35: =I35*J35 -> 255000
I42: =I35 -> 15 | J42: 17000 | K42: =I42*J42 -> 255000

Sheet SLAP
A2: SUBSIDIARY LEDGER ACCOUNT PAYABLE
A5: SUPPLIER | B5: PT. PB Tunggal Perkasa
A6: ID | B6: S001
A8: DATE | B8: DESCRIPTION | C8: REF | D8: DEBET | E8: CREDIT | F8: BALANCE
A9: Juni 2025 | F9: DEBET | G9: CREDIT
A10: 1 | B10: Saldo Awal | C10: √ | G10: 2442000
A11: 6 | B11: Purchase | E11: =PJ!I10 -> 3857500 | G11: =G10+E11 -> 6299500
A12: 13 | B12: Pelunasan | D12: 2442000 | G12: =G11-D12 -> 3857500
A20: SUPPLIER | B20: CV. Shopee Indonesia
A21: ID | B21: S002
A23: DATE | B23: DESCRIPTION | C23: REF | D23: DEBET | E23: CREDIT | F23: BALANCE
A24: Juni 2025 | F24: DEBET | G24: CREDIT
A25: 1 | B25: Saldo Awal | C25: √ | G25: 3885000
A26: 2 | B26: Purchase | E26: 2760000 | G26: =G25+E26 -> 6645000
A35: SUPPLIER | B35: PT. Sumber Lancar
A36: ID | B36: S003
A38: DATE | B38: DESCRIPTION | C38: REF | D38: DEBET | E38: CREDIT | F38: BALANCE
F39: DEBET | G39: CREDIT
A40: Juni 2025
A41: 1 | B41: Saldo Awal | C41: √ | G41: 2553000
A42: 8 | B42: Purchase | E42: =PJ!I11 -> 1998300 | G42: =G41+E42 -> 4551300
A43: 22 | B43: Retur Pembelian | D43: 94350 | G43: =G42-D43 -> 4456950
A51: SUPPLIER | B51: PT. Cahaya Abadi
A52: ID | B52: S004
A54: DATE | B54: DESCRIPTION | C54: REF | D54: DEBET | E54: CREDIT | F54: BALANCE
F55: DEBET | G55: CREDIT
A56: Juni 2025
A57: 1 | B57: Saldo Awal | G57: 1554000
A58: 9 | B58: Purchase | E58: 12757650 | G58: =E58+G57 -> 14311650

Sheet SLAR
A2: SUBSIDIARY LEDGER ACCOUNT RECEIVABE
A5: CUSTOMER | B5: Toko Makmur (Bu Yenne)
A6: ID | B6: C001
A8: DATE | B8: DESCRIPTION | C8: REF | D8: DEBET | E8: CREDIT | F8: BALANCE
F9: DEBET | G9: CREDIT
A10: 1 | B10: Saldo Awal | C10: √ | F10: 5772000
A11: 9 | B11: Pelunasan | E11: 5772000 | F11: =F10-E11 -> 0
A20: CUSTOMER | B20: Sri Lestari
A21: ID | B21: C002
A23: DATE | B23: DESCRIPTION | C23: REF | D23: DEBET | E23: CREDIT | F23: BALANCE
F24: DEBET | G24: CREDIT
A25: 1 | B25: Saldo Awal | C25: √ | F25: 2775000
A26: 7 | B26: Sales | D26: =SJ!E9 -> 6786100 | F26: =F25+D26 -> 9561100
A27: 14 | B27: Pelunasan | E27: 2775000 | F27: =F26-E27 -> 6786100
A28: 28 | B28: Pelunasan | E28: =CRJ!H19 -> 6786100 | F28: =F27-E28 -> 0
A35: CUSTOMER | B35: Mariana Putri Betyani
A36: ID | B36: C003
A38: DATE | B38: DESCRIPTION | C38: REF | D38: DEBET | E38: CREDIT | F38: BALANCE
F39: DEBET | G39: CREDIT
A40: 1 | B40: Saldo Awal | C40: √ | F40: 5106000
A41: 18 | B41: Pelunasan | E41: 5106000 | F41: =SUM(F40-E41) -> 0
A50: CUSTOMER | B50: Toko Sofiyah
A51: ID | B51: C004
A53: DATE | B53: DESCRIPTION | C53: REF | D53: DEBET | E53: CREDIT | F53: BALANCE
F54: DEBET | G54: CREDIT
A55: 1 | B55: Saldo Awal | C55: √ | F55: 4107000
A56: 24 | B56: Sales | D56: =SJ!E11 -> 6328000 | F56: =F55+D56 -> 10435000
A57: 26 | B57: Pelunasan | E57: 4107000 | F57: =F56-E57 -> 6328000

Sheet GL
A2: GENERAL LEDGER
A5: ACCOUNT | B5: CASH IN BANK
A6: NUMBER | B6: 1-1100
A8: DATE | B8: DESCRIPTION | C8: REF | D8: DEBET | E8: CREDIT | F8: BALANCE
F9: DEBET | G9: CREDIT
A10: Juni 2025
A11: 1 | B11: Saldo Awal | C11: √ | F11: 90839200
A12: 31 | B12: Posting | C12: CRJ | D12: =CRJ!M8 -> 39972325 | F12: =SUM(F11+D12) -> 130811525
A13: 31 | B13: Posting | C13: CPJ | E13: =CPJ!O8 -> 8224143 | F13: =SUM(F12-E13) -> 122587382
A20: ACCOUNT | B20: PETTY CASH
A21: NUMBER | B21: 1-1200
A23: DATE | B23: DESCRIPTION | C23: REF | D23: DEBET | E23: CREDIT | F23: BALANCE
F24: DEBET | G24: CREDIT
A25: Juni 2025
A26: 1 | B26: Saldo Awal | C26: √ | F26: ='TB AWAL'!C7 -> 3500000
A27: 31 | B27: Posting | C27: PCJ | E27: =PC!N8 -> 848100 | F27: =SUM(F26-E27) -> 2651900
A35: ACCOUNT | B35: ACCOUNTS RECEIVABLE
A36: NUMBER | B36: 1-1300
A38: DATE | B38: DESCRIPTION | C38: REF | D38: DEBET | E38: CREDIT | F38: BALANCE
F39: DEBET | G39: CREDIT
A40: Juni 2025
A41: 1 | B41: Saldo Awal | C41: √ | F41: ='TB AWAL'!C8 -> 17760000
A42: 31 | B42: Posting | C42: SJ | D42: =SJ!N8 -> 13114100 | F42: =SUM(F41+D42) -> 30874100
A43: 31 | B43: Posting | C43: CRJ | E43: =CRJ!O8 -> 24546100 | F43: =SUM(F42-E43) -> 6328000
A50: ACCOUNT | B50: ALLOWANCE FOR DOUBTFUL DEBT
A51: NUMBER | B51: 1-1400
A53: DATE | B53: DESCRIPTION | C53: REF | D53: DEBET | E53: CREDIT | F53: BALANCE
F54: DEBET | G54: CREDIT
A55: Juni 2025
A56: 1 | B56: Saldo Awal | C56: √ | G56: ='TB AWAL'!D9 -> 2500000
A65: ACCOUNT | B65: MERCHANDISE INVENTORY
A66: NUMBER | B66: 1-1500
A68: DATE | B68: DESCRIPTION | C68: REF | D68: DEBET | E68: CREDIT | F68: BALANCE
F69: DEBET | G69: CREDIT
A70: Juni 2025
A71: 1 | B71: Saldo Awal | C71: √ | F71: ='TB AWAL'!C10 -> 7283500
A72: 31 | B72: Posting | C72: PJ | D72: =PJ!N8 -> 18655000 | F72: =SUM(F71+D72) -> 25938500
A73: 31 | B73: Posting | C73: SJ | E73: =SJ!P8 -> 10320000 | F73: =SUM(F72-E73) -> 15618500
A74: 31 | B74: Posting | C74: CRJ | E74: =CRJ!O9 -> 11772500 | F74: =SUM(F73-E74) -> 3846000
A75: 31 | B75: Posting | C75: GJ | E75: =GJ!L8 -> 85000 | F75: =SUM(F74-E75) -> 3761000
...

Sheet TB
A2: TRIAL BALANCE
A5: ACC.NO | B5: ACCOUNT NAME | C5: DEBIT | D5: CREDIT
A6: ='TB AWAL'!A6 -> 1-1100 | B6: =VLOOKUP(A6,'TB AWAL'!A5:D34,2,FALSE) -> Cash in bank | C6: =GL!F13 -> 122587382
A7: ='TB AWAL'!A7 -> 1-1200 | B7: =VLOOKUP(A7,'TB AWAL'!A6:D35,2,FALSE) -> Petty Cash | C7: =GL!F27 -> 2651900
A8: ='TB AWAL'!A8 -> 1-1300 | B8: =VLOOKUP(A8,'TB AWAL'!A7:D36,2,FALSE) -> Accounts Receivable | C8: =GL!F43 -> 6328000
A9: ='TB AWAL'!A9 -> 1-1400 | B9: =VLOOKUP(A9,'TB AWAL'!A8:D37,2,FALSE) -> Allowance for Doubtful Debt | D9: =GL!G56 -> 2500000
A10: ='TB AWAL'!A10 -> 1-1500 | B10: =VLOOKUP(A10,'TB AWAL'!A9:D38,2,FALSE) -> Merchandise Inventory | C10: =GL!F75 -> 3761000
A11: ='TB AWAL'!A11 -> 1-1600 | B11: =VLOOKUP(A11,'TB AWAL'!A10:D39,2,FALSE) -> Store Supplies | C11: =GL!F87 -> 4168100
A12: ='TB AWAL'!A12 -> 1-1700 | B12: =VLOOKUP(A12,'TB AWAL'!A11:D40,2,FALSE) -> Prepaid Insurance | C12: =GL!F101 -> 1230000
A13: ='TB AWAL'!A13 -> 1-2100 | B13: =VLOOKUP(A13,'TB AWAL'!A12:D41,2,FALSE) -> Equipment at Cost | C13: =GL!F116 -> 7245000
A14: ='TB AWAL'!A14 -> 1-2110 | B14: =VLOOKUP(A14,'TB AWAL'!A13:D42,2,FALSE) -> Equipment Accum Dep | D14: =GL!G132 -> 3421250
A15: ='TB AWAL'!A15 -> 2-1100 | B15: =VLOOKUP(A15,'TB AWAL'!A14:D43,2,FALSE) -> Accounts Payable | D15: =GL!G150 -> 31380100
A16: ='TB AWAL'!A16 -> 2-1200 | B16: =VLOOKUP(A16,'TB AWAL'!A15:D44,2,FALSE) -> Expense Payable | D16: =GL!G163 -> 2680000
A17: ='TB AWAL'!A17 -> 2-1400 | B17: =VLOOKUP(A17,'TB AWAL'!A16:D45,2,FALSE) -> PPN Payable
A18: ='TB AWAL'!A18 -> 2-1500 | B18: =VLOOKUP(A18,'TB AWAL'!A17:D46,2,FALSE) -> PPN Outcome | D18: =GL!G194 -> 4009775
A19: ='TB AWAL'!A19 -> 2-1600 | B19: =VLOOKUP(A19,'TB AWAL'!A18:D47,2,FALSE) -> PPN Income | C19: =GL!F209 -> 2993100
A20: ='TB AWAL'!A20 -> 3-1100 | B20: =VLOOKUP(A20,'TB AWAL'!A19:D48,2,FALSE) -> KOPMEN SBW Capital | D20: =GL!G222 -> 101298000
A21: ='TB AWAL'!A21 -> 3-1200 | B21: =VLOOKUP(A21,'TB AWAL'!A20:D49,2,FALSE) -> KOPMEN SBW Drawing | C21: =GL!F238 -> 600000
A22: ='TB AWAL'!A22 -> 3-1300 | B22: =VLOOKUP(A22,'TB AWAL'!A21:D50,2,FALSE) -> Income Summary
A23: ='TB AWAL'!A23 -> 4-1100 | B23: =VLOOKUP(A23,'TB AWAL'!A22:D51,2,FALSE) -> Sales | D23: =GL!G270 -> 32723950
A24: ='TB AWAL'!A24 -> 4-1200 | B24: =VLOOKUP(A24,'TB AWAL'!A23:D52,2,FALSE) -> Sales Retur
A25: ='TB AWAL'!A25 -> 4-1400 | B25: =VLOOKUP(A25,'TB AWAL'!A24:D53,2,FALSE) -> Freight Collected | D25: =GL!G299 -> 621050
A26: ='TB AWAL'!A26 -> 5-1100 | B26: =VLOOKUP(A26,'TB AWAL'!A25:D54,2,FALSE) -> Cost of goods Sold | C26: =GL!F315 -> 22092500
A27: ='TB AWAL'!A27 -> 5-1200 | B27: =VLOOKUP(A27,'TB AWAL'!A26:D55,2,FALSE) -> Freight Paid | C27: =GL!F329 -> 970000
A28: ='TB AWAL'!A28 -> 6-1100 | B28: =VLOOKUP(A28,'TB AWAL'!A27:D56,2,FALSE) -> Electricity, Internet & Water expenses | C28: =GL!F344 -> 3607143
A29: ='TB AWAL'!A29 -> 6-1200 | B29: =VLOOKUP(A29,'TB AWAL'!A28:D57,2,FALSE) -> Store Supplies Expenses
A30: 6-1300 | B30: Bad Debt Expense | D30: -
A31: ='TB AWAL'!A31 -> 6-1400 | B31: =VLOOKUP(A31,'TB AWAL'!A30:D59,2,FALSE) -> Depreciation Expense | C31: -
A32: ='TB AWAL'!A32 -> 6-1500 | B32: =VLOOKUP(A32,'TB AWAL'!A31:D60,2,FALSE) -> Insurance Expense | C32: -
A33: ='TB AWAL'!A33 -> 6-1700 | B33: =VLOOKUP(A33,'TB AWAL'!A32:D61,2,FALSE) -> Wages & Salaries
A34: ='TB AWAL'!A34 -> 6-1800 | B34: =VLOOKUP(A34,'TB AWAL'!A33:D62,2,FALSE) -> Other Operating Expense | C34: =GL!F421 -> 400000
B35: TOTAL | C35: =SUM(C6:C34) -> 178634125 | D35: =SUM(D9:D25) -> 178634125

Sheet AJ
A2: ADJUSTMENT JOURNAL
A5: DATE | B5: DOC.NO | C5: DESCRIPTION | D5: REFF | E5: DEBIT | F5: CREDIT
A7: Juni
A8: 30 | B8: BM6-1 | C8: Store Supplies Expense | E8: 750000
C9: Store Supplies | F9: =E8 -> 750000
A10: 30 | B10: BM6-1 | C10: Insurance Expense | E10: 150000
C11: Prepaid Insurance | F11: 150000
A12: 30 | B12: BM6-1 | C12: Depreciation Expense | E12: 201250
C13: Equipment Accum Dep | F13: 201250
A14: 30 | B14: BM6-1 | C14: Allowance for Doubtful | E14: 532885
C15: Bad Debt Expense | F15: 532885
A16: 30 | B16: BM6-1 | C16: PPN Outcome | E16: =TB!D18 -> 4009775
C17: PPN Income | F17: =TB!C19 -> 2993100
C18: PPN Payable | F18: =E16-F17 -> 1016675
C24: TOTAL | E24: =SUM(E7:E23) -> 5643910 | F24: =SUM(F7:F23) -> 5643910

Sheet NL
A2: WORK SHEET
A4: ACC.NO | B4: ACCOUNT NAME | C4: TRIAL BALANCE | E4: ADJUSMENT | G4: AFTER ADJUSTMENT | I4: INCOME STATEMENT | K4: FINANCIAL POSITION
C5: DEBIT | D5: CREDIT | E5: DEBIT | F5: CREDIT | G5: DEBIT | H5: CREDIT | I5: DEBIT | J5: CREDIT | K5: DEBIT | L5: CREDIT
A6: {=TB!A6:D34} -> 1-1100 | B6: Cash in bank | C6: 122587382 | D6: 0 | G6: =C6 -> 122587382 | K6: =G6 -> 122587382
A7: 1-1200 | B7: Petty Cash | C7: 2651900 | D7: 0 | G7: =C7 -> 2651900 | K7: =G7 -> 2651900
A8: 1-1300 | B8: Accounts Receivable | C8: 6328000 | D8: 0 | G8: =C8 -> 6328000 | K8: =G8 -> 6328000
A9: 1-1400 | B9: Allowance for Doubtful Debt | C9: 0 | D9: 2500000 | E9: =AJ!E14 -> 532885 | H9: =D9-E9 -> 1967115 | K9: =G9 -> 0 | L9: =H9 -> 1967115
A10: 1-1500 | B10: Merchandise Inventory | C10: 3761000 | D10: 0 | G10: =C10 -> 3761000 | K10: =G10 -> 3761000 | L10: =H10 -> 0
A11: 1-1600 | B11: Store Supplies | C11: 4168100 | D11: 0 | F11: =AJ!F9 -> 750000 | G11: =C11-F11 -> 3418100 | K11: =G11 -> 3418100 | L11: =H11 -> 0
A12: 1-1700 | B12: Prepaid Insurance | C12: 1230000 | D12: 0 | F12: =AJ!F11 -> 150000 | G12: =C12-F12 -> 1080000 | K12: =G12 -> 1080000 | L12: =H12 -> 0
A13: 1-2100 | B13: Equipment at Cost | C13: 7245000 | D13: 0 | G13: =C13 -> 7245000 | K13: =G13 -> 7245000 | L13: =H13 -> 0
A14: 1-2110 | B14: Equipment Accum Dep | C14: 0 | D14: 3421250 | F14: =AJ!F13 -> 201250 | H14: =SUM(D14:F14) -> 3622500 | K14: =G14 -> 0 | L14: =H14 -> 3622500
A15: 2-1100 | B15: Accounts Payable | C15: 0 | D15: 31380100 | H15: =D15 -> 31380100 | K15: =G15 -> 0 | L15: =H15 -> 31380100
A16: 2-1200 | B16: Expense Payable | C16: 0 | D16: 2680000 | H16: =D16 -> 2680000 | L16: =H16 -> 2680000
A17: 2-1400 | B17: PPN Payable | C17: 0 | D17: 0 | F17: =AJ!F18 -> 1016675 | H17: =F17 -> 1016675 | K17: =G17 -> 0 | L17: =H17 -> 1016675
A18: 2-1500 | B18: PPN Outcome | C18: 0 | D18: 4009775 | E18: =AJ!E16 -> 4009775 | H18: =D18-E18 -> 0 | K18: =G18 -> 0 | L18: =H18 -> 0
A19: 2-1600 | B19: PPN Income | C19: 2993100 | D19: 0 | F19: =AJ!F17 -> 2993100 | G19: =C19-F19 -> 0 | K19: =G19 -> 0 | L19: =H19 -> 0
A20: 3-1100 | B20: KOPMEN SBW Capital | C20: 0 | D20: 101298000 | H20: =D20 -> 101298000 | K20: =G20 -> 0 | L20: =H20 -> 101298000
A21: 3-1200 | B21: KOPMEN SBW Drawing | C21: 600000 | D21: 0 | G21: =C21 -> 600000 | K21: =G21 -> 600000 | L21: =H21 -> 0
A22: 3-1300 | B22: Income Summary | C22: 0 | D22: 0 | K22: =G22 -> 0 | L22: =H22 -> 0
A23: 4-1100 | B23: Sales | C23: 0 | D23: 32723950 | H23: =D23 -> 32723950 | J23: =H23 -> 32723950
A24: 4-1200 | B24: Sales Retur | C24: 0 | D24: 0 | J24: =H24 -> 0
A25: 4-1400 | B25: Freight Collected | C25: 0 | D25: 621050 | H25: =D25 -> 621050 | J25: =H25 -> 621050
A26: 5-1100 | B26: Cost of goods Sold | C26: 22092500 | D26: 0 | G26: =C26 -> 22092500 | I26: =G26 -> 22092500 | J26: =H26 -> 0
A27: 5-1200 | B27: Freight Paid | C27: 970000 | D27: 0 | G27: =C27 -> 970000 | I27: =G27 -> 970000 | J27: =H27 -> 0
A28: 6-1100 | B28: Electricity, Internet & Water expenses | C28: 3607143 | D28: 0 | G28: =C28 -> 3607143 | I28: =G28 -> 3607143 | J28: =H28 -> 0
A29: 6-1200 | B29: Store Supplies Expenses | C29: 0 | D29: 0 | E29: =AJ!E8 -> 750000 | G29: =E29 -> 750000 | I29: =G29 -> 750000 | J29: =H29 -> 0
A30: 6-1300 | B30: Bad Debt Expense | C30: 0 | D30: - | F30: =AJ!F15 -> 532885 | G30: =C30 -> 0 | H30: =F30 -> 532885 | I30: =G30 -> 0 | J30: =H30 -> 532885
A31: 6-1400 | B31: Depreciation Expense | C31: - | D31: 0 | E31: =AJ!E12 -> 201250 | G31: =E31 -> 201250 | I31: =G31 -> 201250 | J31: =H31 -> 0
A32: 6-1500 | B32: Insurance Expense | C32: - | D32: 0 | E32: 150000 | G32: =E32 -> 150000 | I32: =G32 -> 150000 | J32: =H32 -> 0
A33: 6-1700 | B33: Wages & Salaries | C33: 0 | D33: 0 | G33: =C33 -> 0 | I33: =G33 -> 0 | J33: =H33 -> 0
A34: 6-1800 | B34: Other Operating Expense | C34: 400000 | D34: 0 | G34: =C34 -> 400000 | I34: =G34 -> 400000 | J34: =H34 -> 0
G35: =C35 -> 0 | I35: =G35 -> 0 | J35: =H35 -> 0
C36: =SUM(C6:C35) -> 178634125 | D36: =SUM(D6:D35) -> 178634125 | E36: =SUM(E6:E35) -> 5643910 | F36: =SUM(F6:F35) -> 5643910 | G36: =SUM(G6:G35) -> 175842275 | H36: =SUM(H6:H35) -> 175842275 | I36: =SUM(I26:I35) -> 28170893 | J36: =SUM(J23:J25:J30) -> 33877885 | K36: =SUM(K6:K21) -> 147671382 | L36: =SUM(L9:L20) -> 141964390
I37: =J36-I36 -> 5706992 | L37: =K38-L36 -> 5706992
I38: =SUM(I36:I37) -> 33877885 | J38: =SUM(J23:J30) -> 33877885 | K38: =SUM(K6:K22) -> 147671382 | L38: =SUM(L36:L37) -> 147671382

Sheet SOCI
A2: STATEMENT OF COMPREHENSIVE INCOME
A5: =NL!B23 -> Sales | B5: =NL!J23 -> 32723950
A6: =NL!B24 -> Sales Retur | B6: =NL!J24 -> 0
A7: =NL!B25 -> Freight Collected | B7: =NL!J25 -> 621050
A8: Net Sales | C8: =B5+B7 -> 33345000
A9: =NL!B26 -> Cost of goods Sold | B9: =-NL!I26 -> -22092500
A10: =NL!B27 -> Freight Paid | B10: =-NL!I27 -> -970000
A11: Total Cost Of Goods Sold | C11: =B9+B10 -> -23062500
A12: Gross Profit | C12: =C8+C11 -> 10282500
A13: =NL!B28 -> Electricity, Internet & Water expenses | B13: =NL!I28 -> 3607143
A14: =NL!B29 -> Store Supplies Expenses | B14: =NL!I29 -> 750000
A15: =NL!B30 -> Bad Debt Expense | B15: =-NL!J30 -> -532885
A16: =NL!B31 -> Depreciation Expense | B16: =NL!I31 -> 201250
A17: =NL!B32 -> Insurance Expense | B17: =NL!I32 -> 150000
A18: =NL!B33 -> Wages & Salaries | B18: =NL!I33 -> 0
A19: =NL!B34 -> Other Operating Expense | B19: =NL!I34 -> 400000
A20: Total Operating Expenses | C20: =SUM(B13:B19) -> 4575508
A21: Operating Profit | C21: =C12-C20 -> 5706992
A23: Net Profit | C23: =C12-C20 -> 5706992

Sheet RES
A2: RETAIRNED EARNING STATEMENT
A5: Modal Awal 1 Juni 2025 | C5: =TB!D20 -> 101298000
A6: Laba Bulan Juni | B6: =SOCI!C23 -> 5706992
A7: Pengambilan Pribadi | B7: =NL!K21 -> 600000
C8: =B6-B7 -> 5106992
A10: Modal akhir 30 Juni 2025 | C10: =SUM(C5:C8) -> 106404992

Sheet SFOP
A2: STATEMENT OF FINANCIAL POSITION
A5: Aktiva Lancar : | C5: Kewajiban dan Ekuitas
A6: =NL!B6 -> Cash in bank | B6: =NL!K6 -> 122587382 | C6: Utang Lancar :
A7: =NL!B7 -> Petty Cash | B7: =NL!K7 -> 2651900 | C7: =NL!B15 -> Accounts Payable | D7: =NL!L15 -> 31380100
A8: =NL!B8 -> Accounts Receivable | B8: =NL!K8 -> 6328000 | C8: =NL!B16 -> Expense Payable | D8: =NL!L16 -> 2680000
A9: =NL!B9 -> Allowance for Doubtful Debt | B9: =-NL!L9 -> -1967115 | C9: =NL!B17 -> PPN Payable | D9: =NL!L17 -> 1016675
A10: =NL!B10 -> Merchandise Inventory | B10: =NL!K10 -> 3761000 | D10: =SUM(D7:D9) -> 35076775
A11: =NL!B11 -> Store Supplies | B11: =NL!K11 -> 3418100
A12: =NL!B12 -> Prepaid Insurance | B12: =NL!K12 -> 1080000
B13: =SUM(B6:B12) -> 137859267 | C13: KOPMEN SBW Capital | D13: =RES!C10 -> 106404992
A14: Aktiva Tetap :
A15: =NL!B13 -> Equipment at Cost | B15: =NL!K13 -> 7245000
A16: =NL!B14 -> Equipment Accum Dep | B16: =-NL!L14 -> -3622500
B17: =SUM(B15:B16) -> 3622500
B20: =B13+B17 -> 141481767 | D20: =D10+D13 -> 141481767

Sheet CFS
A2: CASH FLOW STATEMENT
A5: Arus Kas Dari Aktivitas Operasi
A6: Penerimaan Dari Pelanggan | B6: =CRJ!E23 -> 39972325
A7: Total Penerimaan Operasi | C7: =SUM(B6:B6) -> 39972325
A8: Pembayaran :
A9: Pembayaran Gaji | B9: =CPJ!G9 -> 1725000
A10: ='TB AWAL'!B28 -> Electricity, Internet & Water expenses | B10: =CPJ!M10 -> 3607143
A11: Pembelian Perlengkapan | B11: =PC!F8 -> 448100
A12: Pembyaran Kepada Suplier | B12: =CPJ!E10 -> 2442000
A13: Beban lain-lain | B13: =PC!F9 -> 400000
C14: =SUM(B9:B13) -> 8622243
A15: Arus kas Bersih Aktivitas Operasi | C15: =C7-C14 -> 31350082
A17: Aktivitas Pendanaan
A18: Pengambilan Pribadi | B18: =CPJ!G12 -> 450000
C19: =B18 -> 450000
A20: Total arus Kas bersih | C20: =C15-C19 -> 30900082
A21: Saldo Awal 1 Juni 2025 | C21: ='TB AWAL'!C6+'TB AWAL'!C7 -> 94339200
A22: Kas Dan Setara Kas Akhir | C22: =SUM(C20:C21) -> 125239282

Sheet CJ
A2: CLOSING JOURNAL
A5: DATE | B5: DOC.NO | C5: DESCRIPTION | D5: REFF | E5: DEBIT | F5: CREDIT
C7: Sales | E7: =SOCI!B5 -> 32723950
C8: Bad Debt Expense | E8: =NL!J30 -> 532885
C9: Income Summary | F9: =SUM(E7:E8) -> 33256835
C10: Income Summary | E10: =SUM(F11:F19) -> 28372143
C11: =NL!B26 -> Cost of goods Sold | F11: =NL!I26 -> 22092500
C12: =NL!B27 -> Freight Paid | F12: =NL!I27 -> 970000
C13: =NL!B28 -> Electricity, Internet & Water expenses | F13: =NL!I28 -> 3607143
C14: =NL!B29 -> Store Supplies Expenses | F14: =NL!I29 -> 750000
C15: =NL!B30 -> Bad Debt Expense | F15: =NL!I31 -> 201250
C16: =NL!B31 -> Depreciation Expense | F16: =NL!I31 -> 201250
C17: =NL!B32 -> Insurance Expense | F17: =NL!I32 -> 150000
C18: =NL!B33 -> Wages & Salaries | F18: =NL!I33 -> 0
C19: =NL!B34 -> Other Operating Expense | F19: =NL!I34 -> 400000
C20: Income Summary | E20: =F21 -> 5706992
C21: =NL!B20 -> KOPMEN SBW Capital | F21: =SOCI!C23 -> 5706992
C22: =NL!B20 -> KOPMEN SBW Capital | E22: =F23 -> 600000
C23: =NL!B21 -> KOPMEN SBW Drawing | F23: =RES!B7 -> 600000
C24: Total | E24: =SUM(E7:E23) -> 67935970 | F24: =SUM(F7:F23) -> 67935970

Sheet TBACE
A2: TRIAL BALANCE AFTER CLOSING ENTRIES
A5: ACC.NO | B5: ACCOUNT NAME | C5: DEBET | D5: CREDIT
B6: =NL!B6 -> Cash in bank | C6: =NL!K6 -> 122587382
B7: =NL!B7 -> Petty Cash | C7: =NL!K7 -> 2651900
B8: =NL!B8 -> Accounts Receivable | C8: =NL!K8 -> 6328000
B9: =NL!B9 -> Allowance for Doubtful Debt | D9: =NL!L9 -> 1967115
B10: =NL!B10 -> Merchandise Inventory | C10: =NL!K10 -> 3761000
B11: =NL!B11 -> Store Supplies | C11: =NL!K11 -> 3418100
B12: =NL!B12 -> Prepaid Insurance | C12: =NL!K12 -> 1080000
B13: =NL!B13 -> Equipment at Cost | C13: =NL!K13 -> 7245000
B14: =NL!B14 -> Equipment Accum Dep | D14: =NL!L14 -> 3622500
B15: =NL!B15 -> Accounts Payable | D15: =NL!L15 -> 31380100
B16: =NL!B16 -> Expense Payable | D16: =NL!L16 -> 2680000
B17: =NL!B17 -> PPN Payable | D17: =NL!L17 -> 1016675
B18: =NL!B20 -> KOPMEN SBW Capital | D18: =RES!C10 -> 106404992
B20: Total | C20: =SUM(C6:C18) -> 147071382 | D20: =SUM(D6:D18) -> 147071382
